Traceback (most recent call last):
  File "/Users/michal/Dropbox/22F-210/Book/CS210-text/env/lib/python3.10/site-packages/jupyter_cache/executors/utils.py", line 51, in single_nb_execution
    executenb(
  File "/Users/michal/Dropbox/22F-210/Book/CS210-text/env/lib/python3.10/site-packages/nbclient/client.py", line 1204, in execute
    return NotebookClient(nb=nb, resources=resources, km=km, **kwargs).execute()
  File "/Users/michal/Dropbox/22F-210/Book/CS210-text/env/lib/python3.10/site-packages/nbclient/util.py", line 84, in wrapped
    return just_run(coro(*args, **kwargs))
  File "/Users/michal/Dropbox/22F-210/Book/CS210-text/env/lib/python3.10/site-packages/nbclient/util.py", line 62, in just_run
    return loop.run_until_complete(coro)
  File "/Library/Frameworks/Python.framework/Versions/3.10/lib/python3.10/asyncio/base_events.py", line 641, in run_until_complete
    return future.result()
  File "/Users/michal/Dropbox/22F-210/Book/CS210-text/env/lib/python3.10/site-packages/nbclient/client.py", line 663, in async_execute
    await self.async_execute_cell(
  File "/Users/michal/Dropbox/22F-210/Book/CS210-text/env/lib/python3.10/site-packages/nbclient/client.py", line 965, in async_execute_cell
    await self._check_raise_for_error(cell, cell_index, exec_reply)
  File "/Users/michal/Dropbox/22F-210/Book/CS210-text/env/lib/python3.10/site-packages/nbclient/client.py", line 862, in _check_raise_for_error
    raise CellExecutionError.from_cell_and_msg(cell, exec_reply_content)
nbclient.exceptions.CellExecutionError: An error occurred while executing the following cell:
------------------
city_names = [
  'Beaverton', 'Bend', 'Corvallis', 'Eugene', 
  'Gresham', 'Hillsboro', 'Medford', 'Portland',
  'Salem', 'Springfield']
city_pops = [
    108037, 112264, 65850, 192605,
    124413, 117296, 95003, 705278, 
    195495, 68481]
    
big_city = max_index(city_pops)

print(city_names[i], city_pop[i])
------------------

[0;31m---------------------------------------------------------------------------[0m
[0;31mNameError[0m                                 Traceback (most recent call last)
Input [0;32mIn [7][0m, in [0;36m<cell line: 12>[0;34m()[0m
[1;32m      5[0m city_pops [38;5;241m=[39m [
[1;32m      6[0m     [38;5;241m108037[39m, [38;5;241m112264[39m, [38;5;241m65850[39m, [38;5;241m192605[39m,
[1;32m      7[0m     [38;5;241m124413[39m, [38;5;241m117296[39m, [38;5;241m95003[39m, [38;5;241m705278[39m, 
[1;32m      8[0m     [38;5;241m195495[39m, [38;5;241m68481[39m]
[1;32m     10[0m big_city [38;5;241m=[39m max_index(city_pops)
[0;32m---> 12[0m [38;5;28mprint[39m(city_names[i], [43mcity_pop[49m[i])

[0;31mNameError[0m: name 'city_pop' is not defined
NameError: name 'city_pop' is not defined

