Traceback (most recent call last):
  File "/Users/michal/Dropbox/22F-210/Book/CS210-text/env/lib/python3.10/site-packages/jupyter_cache/executors/utils.py", line 51, in single_nb_execution
    executenb(
  File "/Users/michal/Dropbox/22F-210/Book/CS210-text/env/lib/python3.10/site-packages/nbclient/client.py", line 1204, in execute
    return NotebookClient(nb=nb, resources=resources, km=km, **kwargs).execute()
  File "/Users/michal/Dropbox/22F-210/Book/CS210-text/env/lib/python3.10/site-packages/nbclient/util.py", line 84, in wrapped
    return just_run(coro(*args, **kwargs))
  File "/Users/michal/Dropbox/22F-210/Book/CS210-text/env/lib/python3.10/site-packages/nbclient/util.py", line 62, in just_run
    return loop.run_until_complete(coro)
  File "/Library/Frameworks/Python.framework/Versions/3.10/lib/python3.10/asyncio/base_events.py", line 641, in run_until_complete
    return future.result()
  File "/Users/michal/Dropbox/22F-210/Book/CS210-text/env/lib/python3.10/site-packages/nbclient/client.py", line 663, in async_execute
    await self.async_execute_cell(
  File "/Users/michal/Dropbox/22F-210/Book/CS210-text/env/lib/python3.10/site-packages/nbclient/client.py", line 965, in async_execute_cell
    await self._check_raise_for_error(cell, cell_index, exec_reply)
  File "/Users/michal/Dropbox/22F-210/Book/CS210-text/env/lib/python3.10/site-packages/nbclient/client.py", line 862, in _check_raise_for_error
    raise CellExecutionError.from_cell_and_msg(cell, exec_reply_content)
nbclient.exceptions.CellExecutionError: An error occurred while executing the following cell:
------------------
x = "The global x"
y = "The global y"

def f():
    """Access both local and global variables"""
    print(f"Within f, the value of x is {x}")
    print(f"Within f, the value of y is {y}")
    y = "Something new"   # y is bound in this function
  

print(f"In the global scope, the value of x is {x}")
print(f"In the global scope, the value of y is {y}")  
f()
print("After f ...")
------------------

[0;31m---------------------------------------------------------------------------[0m
[0;31mUnboundLocalError[0m                         Traceback (most recent call last)
Input [0;32mIn [3][0m, in [0;36m<cell line: 13>[0;34m()[0m
[1;32m     11[0m [38;5;28mprint[39m([38;5;124mf[39m[38;5;124m"[39m[38;5;124mIn the global scope, the value of x is [39m[38;5;132;01m{[39;00mx[38;5;132;01m}[39;00m[38;5;124m"[39m)
[1;32m     12[0m [38;5;28mprint[39m([38;5;124mf[39m[38;5;124m"[39m[38;5;124mIn the global scope, the value of y is [39m[38;5;132;01m{[39;00my[38;5;132;01m}[39;00m[38;5;124m"[39m)  
[0;32m---> 13[0m [43mf[49m[43m([49m[43m)[49m
[1;32m     14[0m [38;5;28mprint[39m([38;5;124m"[39m[38;5;124mAfter f ...[39m[38;5;124m"[39m)

Input [0;32mIn [3][0m, in [0;36mf[0;34m()[0m
[1;32m      5[0m [38;5;124;03m"""Access both local and global variables"""[39;00m
[1;32m      6[0m [38;5;28mprint[39m([38;5;124mf[39m[38;5;124m"[39m[38;5;124mWithin f, the value of x is [39m[38;5;132;01m{[39;00mx[38;5;132;01m}[39;00m[38;5;124m"[39m)
[0;32m----> 7[0m [38;5;28mprint[39m([38;5;124mf[39m[38;5;124m"[39m[38;5;124mWithin f, the value of y is [39m[38;5;132;01m{[39;00my[38;5;132;01m}[39;00m[38;5;124m"[39m)
[1;32m      8[0m y [38;5;241m=[39m [38;5;124m"[39m[38;5;124mSomething new[39m[38;5;124m"[39m

[0;31mUnboundLocalError[0m: local variable 'y' referenced before assignment
UnboundLocalError: local variable 'y' referenced before assignment

